<?xml version="1.0" ?>
<!-- =================================================================================== -->
<!-- |    This document was autogenerated by xacro from quori.xacro                    | -->
<!-- |    EDITING THIS FILE BY HAND IS NOT RECOMMENDED                                 | -->
<!-- =================================================================================== -->
<robot name="quori">
  <link name="quori/base_link">
    <inertial>
      <origin rpy="0 0 0" xyz="0 0 0.23"/>
      <mass value="2"/>
      <inertia ixx="0.052" ixy="0" ixz="0" iyy="0.052" iyz="0" izz="0.031"/>
    </inertial>
    <visual>
      <origin rpy="0 0 -1.57079632679" xyz="0.02 0 -0.2007174"/>
      <geometry>
        <mesh filename="file:///home/jorge/quori_ws/src/quori_simulation/meshes/180915_Lower_Torso.dae"/>
      </geometry>
    </visual>
  </link>
  <link name="quori/body_upper">
    <inertial>
      <origin rpy="0 0 0" xyz="0 0 -0.01"/>
      <mass value="26.75"/>
      <inertia ixx="2.5" ixy="0" ixz="0" iyy="2.5" iyz="0" izz="0.134"/>
    </inertial>
    <visual>
      <origin rpy="0 0 -1.57079632679" xyz="0.02 0 -0.5476974"/>
      <geometry>
        <mesh filename="file:///home/jorge/quori_ws/src/quori_simulation/meshes/0917_Upper_Torso+Waist.dae"/>
      </geometry>
    </visual>
  </link>
  <joint name="waist_pitch" type="revolute">
    <origin rpy="0 0 0" xyz="0 0 0.34798"/>
    <parent link="quori/base_link"/>
    <child link="quori/body_upper"/>
    <axis xyz="0 -1 0"/>
    <limit effort="1" lower="-0.47123889803846897" upper="0.2111848394913139" velocity="1"/>
  </joint>
  <link name="quori/r_shoulder">
    <inertial>
      <origin rpy="0 0 0" xyz="0 0 0"/>
      <mass value="0.0"/>
      <inertia ixx="0.0" ixy="0" ixz="0" iyy="0.0" iyz="0" izz="0.0"/>
    </inertial>
  </link>
  <joint name="r_shoulder_pitch" type="revolute">
    <origin rpy="0 0 0" xyz="0.015 -0.16403066 0.43021758"/>
    <parent link="quori/body_upper"/>
    <child link="quori/r_shoulder"/>
    <axis xyz="0 -1 0"/>
    <limit effort="1" lower="-2.4" upper="2.4" velocity="1"/>
  </joint>
  <link name="quori/r_arm_upper">
    <inertial>
      <origin rpy="0 0 0" xyz="0 0 0"/>
      <mass value="0.00"/>
      <inertia ixx="0.0" ixy="0" ixz="0" iyy="0.0" iyz="0" izz="0.0"/>
    </inertial>
    <visual>
      <origin rpy="-1.57079632679 0 0" xyz="0.165 -0.9765 -0.137"/>
      <geometry>
        <mesh filename="file:///home/jorge/quori_ws/src/quori_simulation/meshes/0917_Upper_Arm+gear_right.dae"/>
      </geometry>
    </visual>
  </link>
  <joint name="r_shoulder_roll" type="revolute">
    <origin rpy="0 0 0" xyz="0 0 0"/>
    <parent link="quori/r_shoulder"/>
    <child link="quori/r_arm_upper"/>
    <axis xyz="-1 0 0"/>
    <limit effort="1" lower="-1.1" upper="1.1" velocity="1"/>
  </joint>
  <link name="quori/r_arm_upper2lower">
    <inertial>
      <origin rpy="0 0 0" xyz="0 0 0.3"/>
      <mass value="0.19"/>
      <inertia ixx="0.006" ixy="0" ixz="0" iyy="0.006" iyz="0" izz="0.0"/>
    </inertial>
    <visual>
      <origin rpy="-1.57079632679 0 0" xyz="0 -0.13 0"/>
      <geometry>
        <cylinder length="0.08" radius="0.015"/>
      </geometry>
      <material name="white"/>
    </visual>
  </link>
  <joint name="r_arm_upper2lower_j" type="fixed">
    <parent link="quori/r_arm_upper"/>
    <child link="quori/r_arm_upper2lower"/>
  </joint>
  <link name="quori/r_arm_lower">
    <inertial>
      <origin rpy="0 0 0" xyz="0 0 0"/>
      <mass value="0.00"/>
      <inertia ixx="0.0" ixy="0" ixz="0" iyy="0.0" iyz="0" izz="0.0"/>
    </inertial>
    <visual>
      <origin rpy="1.570759635 1.570759635 0" xyz="0 0 0"/>
      <geometry>
        <mesh filename="file:///home/jorge/quori_ws/src/quori_simulation/meshes/0917_Lower_Arm_right.dae"/>
      </geometry>
    </visual>
  </link>
  <joint name="r_elbow_pitch" type="fixed">
    <origin rpy="0 0 0" xyz="0 -0.15 0"/>
    <parent link="quori/r_arm_upper"/>
    <child link="quori/r_arm_lower"/>
  </joint>
  <link name="quori/l_shoulder">
    <inertial>
      <origin rpy="0 0 0" xyz="0 0 0"/>
      <mass value="0.0"/>
      <inertia ixx="0.0" ixy="0" ixz="0" iyy="0.0" iyz="0" izz="0.0"/>
    </inertial>
  </link>
  <joint name="l_shoulder_pitch" type="revolute">
    <origin rpy="0 0 0" xyz="0.015 0.16403066 0.43021758"/>
    <parent link="quori/body_upper"/>
    <child link="quori/l_shoulder"/>
    <axis xyz="0 -1 0"/>
    <limit effort="1" lower="-2.4" upper="2.4" velocity="1"/>
  </joint>
  <link name="quori/l_arm_upper">
    <inertial>
      <origin rpy="0 0 0" xyz="0 0 0"/>
      <mass value="0.00"/>
      <inertia ixx="0.0" ixy="0" ixz="0" iyy="0.0" iyz="0" izz="0.0"/>
    </inertial>
    <visual>
      <origin rpy="-1.57079632679 0 -3.14" xyz="0.165 0.9765 -0.137"/>
      <geometry>
        <mesh filename="file:///home/jorge/quori_ws/src/quori_simulation/meshes/0917_Upper_Arm+gear_left.dae"/>
      </geometry>
    </visual>
  </link>
  <joint name="l_shoulder_roll" type="revolute">
    <origin rpy="0 0 0" xyz="0 0 0"/>
    <parent link="quori/l_shoulder"/>
    <child link="quori/l_arm_upper"/>
    <axis xyz="1 0 0"/>
    <limit effort="1" lower="-1.1" upper="1.1" velocity="1"/>
  </joint>
  <link name="quori/l_arm_upper2lower">
    <inertial>
      <origin rpy="0 0 0" xyz="0 0 0.3"/>
      <mass value="0.19"/>
      <inertia ixx="0.006" ixy="0" ixz="0" iyy="0.006" iyz="0" izz="0.0"/>
    </inertial>
    <visual>
      <origin rpy="-1.57079632679 0 0" xyz="0 0.13 0"/>
      <geometry>
        <cylinder length="0.08" radius="0.015"/>
      </geometry>
      <material name="white"/>
    </visual>
  </link>
  <joint name="l_arm_upper2lower_j" type="fixed">
    <parent link="quori/l_arm_upper"/>
    <child link="quori/l_arm_upper2lower"/>
  </joint>
  <link name="quori/l_arm_lower">
    <inertial>
      <origin rpy="0 0 0" xyz="0 0 0"/>
      <mass value="0.00"/>
      <inertia ixx="0.0" ixy="0" ixz="0" iyy="0.0" iyz="0" izz="0.0"/>
    </inertial>
    <visual>
      <origin rpy="-1.570759635 -1.570759635 0" xyz="0 0 0"/>
      <geometry>
        <mesh filename="file:///home/jorge/quori_ws/src/quori_simulation/meshes/0917_Lower_Arm_left.dae"/>
      </geometry>
    </visual>
  </link>
  <joint name="l_elbow_pitch" type="fixed">
    <origin rpy="0 0 0" xyz="0 0.15 0"/>
    <parent link="quori/l_arm_upper"/>
    <child link="quori/l_arm_lower"/>
  </joint>
  <link name="quori/head">
    <inertial>
      <origin rpy="0 0 0" xyz="0 0 0"/>
      <mass value="1.9"/>
      <inertia ixx="0.008" ixy="0" ixz="0" iyy="0.0056" iyz="0" izz="0.0056"/>
    </inertial>
    <visual>
      <origin xyz="0 0 0.085"/>
      <geometry>
        <sphere radius="0.11"/>
      </geometry>
      <material name="white"/>
    </visual>
    <visual>
      <origin rpy="0 0 -1.57079632679" xyz="0.01 0 -1.11"/>
      <geometry>
        <mesh filename="file:///home/jorge/quori_ws/src/quori_simulation/meshes/0917_Helmet_Duripod.dae"/>
      </geometry>
    </visual>
  </link>
  <joint name="neck" type="fixed">
    <origin rpy="0 0 0" xyz="0 0 0.554"/>
    <parent link="quori/body_upper"/>
    <child link="quori/head"/>
  </joint>
  <joint name="head_camera_optical_joint" type="fixed">
    <origin rpy="-1.57079632679 0 -1.57079632679" xyz="0 0 0"/>
    <parent link="quori/head_camera"/>
    <child link="quori/head_camera_optical"/>
  </joint>
  <link name="quori/head_camera_optical">
  </link>
  <link name="quori/head_camera">
    <inertial>
      <origin rpy="0 0 0" xyz="0 0 0"/>
      <mass value="0.3"/>
      <inertia ixx="0.0004" ixy="0" ixz="0" iyy="0.0001" iyz="0" izz="0.0004"/>
    </inertial>
    <visual>
      <geometry>
        <box size="0.04 0.11 0.04"/>
      </geometry>
      <origin rpy="0 0 0" xyz="0 0 -0"/>
      <material name="black"/>
    </visual>
  </link>
  <joint name="camera_pitch" type="fixed">
    <origin rpy="0 0 0" xyz="0.055 0 0.21"/>
    <parent link="quori/head"/>
    <child link="quori/head_camera"/>
  </joint>
  <link name="quori/head_mic">
    <inertial>
      <origin rpy="0 0 0" xyz="0 0 0"/>
      <mass value="0.05"/>
      <inertia ixx="0.0" ixy="0" ixz="0" iyy="0.0" iyz="0" izz="0.0"/>
    </inertial>
    <visual>
      <geometry>
        <cylinder length="0.002" radius="0.03"/>
      </geometry>
      <origin rpy="0 0 0" xyz="0 0 -0"/>
      <material name="blue"/>
    </visual>
  </link>
  <joint name="mic_array" type="fixed">
    <origin rpy="0 -.3 0" xyz="-0.008 0 0.218"/>
    <parent link="quori/head"/>
    <child link="quori/head_mic"/>
  </joint>
  <material name="ramsis/base_link_material">
    <color rgba="0 0 0 1"/>
  </material>
  <material name="ramsis/laser_scanner_material">
    <color rgba="0.3 0.3 0.3 1"/>
  </material>
  <link name="ramsis/base_link_diff">
    <inertial>
      <origin rpy="0 0 0" xyz="0 0 0.1013587"/>
      <mass value="9.8"/>
      <inertia ixx="0.176" ixy="0" ixz="0" iyy="0.176" iyz="0" izz="0.285"/>
    </inertial>
    <visual>
      <origin rpy="0 0 0" xyz="0 0 0.1013587"/>
      <geometry>
        <cylinder length="0.2027174" radius="0.2413"/>
      </geometry>
      <material name="ramsis/base_link_material"/>
    </visual>
  </link>
  <link name="ramsis/base_laser_scanner">
    <inertial>
      <mass value="0.17"/>
      <inertia ixx="0.0001" ixy="0" ixz="0" iyy="0.0001" iyz="0" izz="0.0001"/>
    </inertial>
    <visual>
      <geometry>
        <cylinder length="0.025" radius="0.05"/>
      </geometry>
      <origin rpy="0 0 0" xyz="0 0 -0"/>
      <material name="ramsis/laser_scanner_material"/>
    </visual>
  </link>
  <joint name="laser_scanner_joint" type="fixed">
    <origin rpy="0 0.0 -1.5707" xyz="0.152 0 0.156"/>
    <parent link="ramsis/base_link_diff"/>
    <child link="ramsis/base_laser_scanner"/>
  </joint>
  <link name="ramsis/turret_link">
  </link>
  <link name="ramsis/base_link">
  </link>
  <link name="ramsis/l_wheel_link">
    <inertial>
      <origin rpy="0 0 0" xyz="0 0 0"/>
      <mass value="0.0"/>
      <inertia ixx="0.0" ixy="0" ixz="0" iyy="0.0" iyz="0" izz="0.0"/>
    </inertial>
  </link>
  <link name="ramsis/r_wheel_link">
    <inertial>
      <origin rpy="0 0 0" xyz="0 0 0"/>
      <mass value="0.0"/>
      <inertia ixx="0.0" ixy="0" ixz="0" iyy="0.0" iyz="0" izz="0.0"/>
    </inertial>
  </link>
  <joint name="ramsis/wheel_axle_joint" type="fixed">
    <origin xyz="0.1 0 -0.075"/>
    <parent link="ramsis/wheel_axle"/>
    <child link="ramsis/base_link_diff"/>
  </joint>
  <joint name="turret2base" type="fixed">
    <origin xyz="0 0 -0.2027174"/>
    <parent link="ramsis/turret_link"/>
    <child link="ramsis/base_link"/>
  </joint>
  <link name="ramsis/wheel_axle">
  </link>
  <joint name="l_wheel" type="continuous">
    <origin rpy="0 0 0" xyz="0 0.12284075 0"/>
    <parent link="ramsis/wheel_axle"/>
    <child link="ramsis/l_wheel_link"/>
    <axis xyz="0 1 0"/>
    <limit effort="1" velocity="0.5"/>
  </joint>
  <joint name="r_wheel" type="continuous">
    <origin rpy="0 0 0" xyz="0 -0.12284075 0"/>
    <parent link="ramsis/wheel_axle"/>
    <child link="ramsis/r_wheel_link"/>
    <axis xyz="0 1 0"/>
    <limit effort="1" velocity="0.5"/>
  </joint>
  <joint name="turret" type="continuous">
    <origin rpy="0 0 0" xyz="0 0 0.2027174"/>
    <parent link="ramsis/base_link_diff"/>
    <child link="ramsis/turret_link"/>
    <axis xyz="0 0 1"/>
    <limit effort="1" velocity="3"/>
  </joint>
  <quori_kinematics/>
  <ramsis_kinematics/>
  <!-- Join the quori robot to the ramsis robot's turret joint -->
  <joint name="ramsis_quori_connector" type="fixed">
    <parent link="ramsis/turret_link"/>
    <child link="quori/base_link"/>
  </joint>
</robot>
