To complete your .sdf file, I'll add more components to the MyRobotModel, including additional links for arms and a head, assuming you have corresponding mesh files for these parts. Please adjust the mesh file names and paths according to your actual files.

xml

<?xml version="1.0" ?>
<sdf version="1.6">
  <model name="MyRobotModel">
    <!-- Body Link -->
    <link name="body">
      <visual name="body_visual">
        <geometry>
          <mesh>
            <uri>model://quori/meshes/0917_Upper_Torso+Waist.dae</uri>
            <scale>1 1 1</scale>
          </mesh>
        </geometry>
      </visual>
    </link>

    <!-- Left Arm Link -->
    <link name="left_arm">
      <visual name="left_arm_visual">
        <geometry>
          <mesh>
            <uri>model://quori/meshes/0917_Lower_Arm_left.dae</uri>
            <scale>1 1 1</scale>
          </mesh>
        </geometry>
      </visual>
    </link>

    <!-- Right Arm Link -->
    <link name="right_arm">
      <visual name="right_arm_visual">
        <geometry>
          <mesh>
            <uri>model://quori/meshes/0917_Lower_Arm_right.dae</uri>
            <scale>1 1 1</scale>
          </mesh>
        </geometry>
      </visual>
    </link>

    <!-- Head Link -->
    <link name="head">
      <visual name="head_visual">
        <geometry>
          <mesh>
            <uri>model://quori/meshes/0917_Helmet_Duripod.dae</uri>
            <scale>1 1 1</scale>
          </mesh>
        </geometry>
      </visual>
    </link>

    <!-- Example Joint (connects body to head) -->
    <joint name="neck" type="revolute">
      <parent>body</parent>
      <child>head</child>
      <axis>
        <xyz>0 0 1</xyz>
        <limit>
          <lower>-1</lower>
          <upper>1</upper>
          <effort>10</effort>
          <velocity>1</velocity>
        </limit>
      </axis>
      <pose>0 0 1 0 0 0</pose> <!-- Adjust this pose based on your model's structure -->
    </joint>

    <!-- Additional joints for left_arm and right_arm would go here -->
  </model>
</sdf>

